Workbook

Sheet Speech
B1: SPEECH
B3: Preguntas Generales
B4: Preguntas | C4: Posibles respuestas (Formato de Respuestas) | D4: Tabla a la que va a la información, en caso de ser nueva información
B5: Nombre del Desarrollador
B6: ¿Cuál es el id de tu historia ?
B7: ¿Cuál es el alcance de la historia ? | C7: (Historia de Usuario) Como usuario {tipoUsuario} Quiero {Accion a realizar} Para {Objetivo final}
B8: ¿Qué repositorios vas a utilizar para solucionar la historia? | C8: ERP-FRONT-V1 ERPLogistica PuntoVenta
B10: Preguntas Para Front
B11: TABLAS: 1. TipoControl | C11: TABLAS: 1. Control | D11: TABLAS: 1. TipoEvento 2. Evento | E11: TABLAS: 1. Ruta 2. Interfaz 3. RutaInterfaz | F11: TABLAS: 1. Modulo | G11: TABLAS: 1. SubModulo | H11: TABLAS: 1. Interfaz 2. ContenedorComponente 3. InterfazContenedor | I11: TABLAS: 1. Servicios 2. Evento 3. EventosServicio
B12: Ejm: button | C12: Ejm: Buscar | D12: Ejm: onclick | E12: Ejm: /admin/documentos/busqueda | F12: Ejm: Facturación | G12: Ejm: Búsqueda comprobantes | H12: Ejm: 4111.component.html | I12: Ejm: GET - Contabilidad/api/v1/dominio/parametros
B13: Tipo de Control Modificado | C13: Nombre de Control | D13: Evento que se aplica a Elemento (que genera alguna accion en interfaz) | E13: Ruta de Interfaz | F13: Modulo | G13: Submodulo | H13: Nombre documento donde se encuentra Control | I13: Ruta de Servicio que llama Control
B18: Preguntas Para Back
B19: TABLAS: 1. Servicios | D19: TABLAS: 1. Fuente 2. FuenteServicio
B20: Servicio o Web Socket | C20: Ruta | D20: Redis | E20: Kafka | F20: S3 | G20: SQL | H20: Vault (solo certificación) | I20: Descripción
B25: Resultados
B26: Valoraciones QA | C26: Posibles respuestas (Formato de Respuestas)
B27: Riesgo Valorado o Sugerido por QA | C27: -
B28: Observaciones | C28: -
B29: Ingreso o Verificación de data ingresada a Matriz de Trazabilidad | C29: Se encuentra evidenciado en el kickoff del MVP
B30: Revision de Matriz de trazabilidad | C30: Evidencia
B31: Conclusiones

Sheet Leyenda Speech
B1: LEYENDA SPEECH
B3: Preguntas Generales
B4: Preguntas | C4: Posibles respuestas (Formato de Respuestas) | D4: Tabla a la que va a la infromacion, en caso de ser nueva informacion
B5: Nombre del Desarrollador
B6: ¿Cuál es el id de tu historia ?
B7: ¿Cuál es el alcance de la historia ? | C7: (Historia de Usuario) Como usuario {tipoUusario} Quiero {Accion a realizar} Para {Objetivo final}
B8: ¿Qué repositorios vas a utilizar para solucionar la historia ? | C8: ERP-FRONT-V1 ERPLogistica PuntoVenta
B10: Preguntas Para Front
B11: Preguntas | C11: Posibles respuestas (Formato de Respuestas) | D11: Tabla a la que va a la infromacion, en caso de ser nueva informacion
B12: ¿Va a requerir algún cambio en front?
B13: En front ¿Al realizar que evento o accion se pueden reflejar los cambios o mejoras segun la historia? | C13: Al hacer {tipoEvento} en el {tipoControl} {nombreContol} ubicado en la ruta {nombreRuta}. | D13: Se obtiene el Modulo, submodulo, ruta, ruta interfaz e Interfaz. TipoEvento
B14: ¿En qué Archivo (.html o .ts) se encuentra el elemento de front modificado o aumentado o que genera la accion de cambio segun la historia? | C14: Se encuentra en el archivo {nombreDelArchivo} | D14: Se obtiene ContenedorComponete, InterfazContenedor
B15: El elemto html modificado o aumentado en front, ¿Qué tipo de elemento es visulamente? | C15: Boton, input, Select, etc | D15: Control, tipoControl
B16: ¿Al realizar una accion sobre el elemento html, este llama a algún servicio REST o web socket? Indicar el nombre de la ruta y nombre del repositorio al que pertenece | C16: Web socket Nombre ruta: Nombre repositorio: | D16: Evento Servicio Evento Servicio
B18: Preguntas Para Back
B19: Preguntas | C19: Posibles respuestas (Formato de Respuestas) | D19: Tabla a la que va a la infromacion, en caso de ser nueva informacion
B21: ¿Se va a modificar o añadir un servicio REST o web socket? | C21: Si, {nonbre de ruta de servicio} | D21: Servicio
B22: Em base a el servicio modificado o añadido ¿Se ha modificado clave en redis? | C22: Si, y el nombre es {nombre_clave} | D22: Fuente FuenteServicio
B23: Em base a el servicio modificado o añadido ¿Se ha modificado topic en Kafka? | C23: Si, y el nombre es {nombre_topic} | D23: Fuente FuenteServicio
B24: ¿El servicio en cuestion agrega o modifica funcionalidad o inserta datos en la Base de datos? | C24: Si, y el nombre el recurso es un {storeProcedure, tabla, etc } y se llama {nombre del recurso} y el nombre de columna {nombreColumna} en la BD {NombreDeBD} | D24: Fuente FuenteServicio
B25: ¿El servicio en cuestion agrega o modifica funcionalidad o inserta datos en algun Bucket del S3? | C25: Si, y el nombre es { Nombre Bucket} y su nomenclatura para guardado de documenyo es {nomeclatura}. | D25: Fuente FuenteServicio
B30: Resultados
B31: Valoraciones QA | C31: Posibles respuestas (Formato de Respuestas)
B32: Riesgo Valorado o Sugerido por QA | C32: Muy Alto, Alto, Bajo ...
B33: Observaciones
B34: Ingreso o Verificación de data ingresada a Matriz de Trazabilidad | C34: Evidencia (captura ejecucion de script, etc)
B35: Revision de Matriz de trazabilidad | C35: Evidencia
B36: Conclusiones

Sheet Test Case
B1: MVP Request | E1: =CONCATENATE("https://redmine.sreasons.com/issues/",C1) -> https://redmine.sreasons.com/issues/
E2: https://erpperucrt.smartclic.pe/auth/login
A3: Código | B3: Sección | C3: Detalle Sección | D3: RESPONSABLE | E3: Cantidad incidencias | F3: Incidencias Validadas
A4: =CONCATENATE("ERP2CRT-01",TEXT($C$1,"00"),"0",ROW(A4) - ROW($A$4) + 1) -> ERP2CRT-010001 | E4: =COUNTIF('Test Run'!A:A,A4) -> 0 | F4: =COUNTIFS('Test Run'!A:A,A4,'Test Run'!H:H,"Corregido") -> 0
A5: =CONCATENATE("ERP2CRT-01",TEXT($C$1,"00"),"0",ROW(A5) - ROW($A$4) + 1) -> ERP2CRT-010002 | E5: =COUNTIF('Test Run'!A:A,A5) -> 0 | F5: =COUNTIFS('Test Run'!A:A,A5,'Test Run'!H:H,"Corregido") -> 0
A6: =CONCATENATE("ERP2CRT-01",TEXT($C$1,"00"),"0",ROW(A6) - ROW($A$4) + 1) -> ERP2CRT-010003 | E6: =COUNTIF('Test Run'!A:A,A6) -> 0 | F6: =COUNTIFS('Test Run'!A:A,A6,'Test Run'!H:H,"Corregido") -> 0
A7: =CONCATENATE("ERP2CRT-01",TEXT($C$1,"00"),"0",ROW(A7) - ROW($A$4) + 1) -> ERP2CRT-010004 | E7: =COUNTIF('Test Run'!A:A,A7) -> 0 | F7: =COUNTIFS('Test Run'!A:A,A7,'Test Run'!H:H,"Corregido") -> 0
A8: =CONCATENATE("ERP2CRT-01",TEXT($C$1,"00"),"REG") -> ERP2CRT-0100REG | E8: =COUNTIF('Test Run'!A:A,A8) -> 0 | F8: =COUNTIFS('Test Run'!A:A,A8,'Test Run'!H:H,"Corregido") -> 0
E9: =COUNTIF('Test Run'!A:A,A9) -> 0 | F9: =COUNTIFS('Test Run'!A:A,A9,'Test Run'!H:H,"Corregido") -> 0
E10: =COUNTIF('Test Run'!A:A,A10) -> 0 | F10: =COUNTIFS('Test Run'!A:A,A10,'Test Run'!H:H,"Corregido") -> 0
E11: =COUNTIF('Test Run'!A:A,A11) -> 0 | F11: =COUNTIFS('Test Run'!A:A,A11,'Test Run'!H:H,"Corregido") -> 0
E12: =COUNTIF('Test Run'!A:A,A12) -> 0 | F12: =COUNTIFS('Test Run'!A:A,A12,'Test Run'!H:H,"Corregido") -> 0
E13: =COUNTIF('Test Run'!A:A,A13) -> 0 | F13: =COUNTIFS('Test Run'!A:A,A13,'Test Run'!H:H,"Corregido") -> 0
E14: =COUNTIF('Test Run'!A:A,A14) -> 0 | F14: =COUNTIFS('Test Run'!A:A,A14,'Test Run'!H:H,"Corregido") -> 0
E15: =COUNTIF('Test Run'!A:A,A15) -> 0 | F15: =COUNTIFS('Test Run'!A:A,A15,'Test Run'!H:H,"Corregido") -> 0
E16: =COUNTIF('Test Run'!A:A,A16) -> 0 | F16: =COUNTIFS('Test Run'!A:A,A16,'Test Run'!H:H,"Corregido") -> 0
E17: =COUNTIF('Test Run'!A:A,A17) -> 0 | F17: =COUNTIFS('Test Run'!A:A,A17,'Test Run'!H:H,"Corregido") -> 0
E18: =COUNTIF('Test Run'!A:A,A18) -> 0 | F18: =COUNTIFS('Test Run'!A:A,A18,'Test Run'!H:H,"Corregido") -> 0
C19: =E19-F19 -> 0 | E19: =SUM(E4:E13) -> 0 | F19: =SUM(F4:F13) -> 0
C20: Incidencias Pendientes | E20: Incidencias encontradas | F20: Incidencias validadas

Sheet Test Run Minimos
A1: CODIGO | B1: Test Run Mínimo | C1: Pasos | D1: Resultado esperado | E1: Criticidad | F1: Check de Desarrollador | G1: Evidencia Desarrollador | H1: Observaciones
F2: FALSE
F3: FALSE
F4: FALSE
F5: FALSE
F6: FALSE
F7: FALSE
F8: FALSE
F9: FALSE
F10: FALSE
F11: FALSE
F12: FALSE
F13: FALSE
... F20: FALSE

Sheet Test Run
A1: Codigo | B1: Test | C1: Pasos | D1: Responsable Revisión | E1: Nivel de detección | F1: Criticidad | G1: Tipo de Incidencia | H1: Estado Revision | I1: Resultados / comentarios | J1: Referencia | K1: Fecha de Revisión | L1: Fecha de Validación | M1: Estado Desarrollo | N1: Historia | O1: Responsable de Corrección | P1: Complejidad | Q1: Comentario

Sheet Checklist QA
A1: Módulo | B1: Descripción | C1: Fecha | D1: Revisado | E1: Resultado | F1: Comentario
D2: FALSE
D3: FALSE
D4: FALSE
D5: FALSE
D6: FALSE
D7: FALSE
D8: FALSE
D9: FALSE
D10: FALSE
D11: FALSE
D12: FALSE
D13: FALSE
... D148: FALSE

Sheet Regresión ERP2
B1: Productos y Stock | D1: Responsable | E1: Ok crt | F1: Responsable | G1: Ok Prd | H1: Observaciones
B2: Filtros en lista de ítems | C2: - Verificar que la información se muestre de acuerdo a los filtros | E2: FALSE | G2: FALSE
B3: Carga masiva de ítems | C3: - Crear ítem (producto, servicio, insumo, combo, receta, lista de productos) de forma masiva - Ver ítem creado en lista de ítems - Ver almacenes en los que se creó el ítem | E3: FALSE | G3: FALSE
B4: Crear Item | C4: - Crear ítem (producto, servicio, insumo, combo, receta, lista) de forma individual - Ver ítem creado en lista de ítems - Verificar la información en Ver Ítem - Verificar que los datos sean correctos en bitácora - Verificar variantes, equivalencias, selectores | E4: FALSE | G4: FALSE
B5: Editar ítem | C5: - Verificar nueva información | E5: FALSE | G5: FALSE
B6: Clonar ítem | C6: - Ver nuevo ítem creado | E6: FALSE | G6: FALSE
B7: Actualización masiva de ítems | C7: - Ver nueva información de ítems | E7: FALSE | G7: FALSE
B8: Actualización masiva de stock de ítems | C8: - Ver nuevo stock de ítems | E8: FALSE | G8: FALSE
B9: Exportar ítems | C9: - Descarga correcta de información | E9: FALSE | G9: FALSE
B10: Movimientos
B11: Creación de proveedor desde nuevo ingreso de almacén | C11: - Registrar nuevo proveedor - Buscar proveedor creado - Usar proveedor creado | E11: FALSE | G11: FALSE
B12: Creación de cliente desde nueva salida de almacén | C12: - Registrar nuevo cliente - Buscar cliente creado - Usar cliente creado | E12: FALSE | G12: FALSE
B13: Realizar ingreso de almacén | C13: - Ver movimiento de inventario - Ver movimiento en Kardex - Ver formatos de impresión - Enviar por whatsapp y correo - Descargar PDF | E13: FALSE | G13: FALSE
B14: Realizar salida de almacén sin despachar | C14: - Ver descargo de inventario - Ver movimiento en kardex - Ver formatos de impresión - Enviar por whatsapp y correo - Descargar PDF - Despachar salida - Ver bitácora (eventos de creación y actualización) | E14: FALSE | G14: FALSE
B15: Realizar un ajuste | C15: - Ver descargo de inventario - Agregar campos adicionales - Ver bitácora (eventos de creación y actualización) | E15: FALSE | G15: FALSE
B16: Realizar un traslado (con o sin confirmación) | C16: - Ver descargo de inventario - Ver bitácora (eventos de creación y actualización) | E16: FALSE | G16: FALSE
B17: Editar un movimiento de almacén | C17: - Ver cambios de stock en el ítem - Ver información en ver movimiento | E17: FALSE | G17: FALSE
B18: Clonar un movimiento de almacén | C18: - Ver cambios de stock en el ítem - Ver información en ver movimiento | E18: FALSE | G18: FALSE
B19: Realizar movimiento masivo | C19: - Verificar movimientos creados desde lista - Ver descargos de stock | E19: FALSE | G19: FALSE
B20: Imprimir y enviar un movimiento desde la lista de movimientos | C20: - Ver acciones del movimiento - Imprimir en A4 y ticket - Enviar por whatsapp y correo - Descargar PDF | E20: FALSE | G20: FALSE
B21: Eliminar un movimiento de almacén | C21: - Verificar aumento o disminución de stock | E21: FALSE | G21: FALSE
B22: Exportar movimientos | C22: - Filtrar algunos movimientos y exportar movimientos PDF y Excel - Descarga básica y descarga con todos los campos | E22: FALSE | G22: FALSE
B23: Exportar movimientos detallados | C23: - Filtrar algunos movimientos y exportar movimientos detallados PDF y Excel - Descarga básica y descarga con todos los campos | E23: FALSE | G23: FALSE
B24: Movimientos rápidos
B25: Realizar un ingreso rápido de stock de producto | C25: - Verificar aumento de stock | E25: FALSE | G25: FALSE
B26: Realizar una salida rápida de stock de insumo | C26: - Verificar salida de stock | E26: FALSE | G26: FALSE
B27: Configuraciones
B28: Búsqueda de configuraciones | C28: - Revisar redireccionamiento - Revisar correcta foto - Revisar correcto nombre | E28: FALSE | G28: FALSE
B29: Configuración del sistema
B30: Sucursales | C30: - Sin ruc: Solo tendra 3 documentos habilitados Cotización, nota de venta y pedidos - Con ruc: Todos los documentos habilitados | E30: FALSE | G30: FALSE
B31: Caja de ventas | C31: - Sin ruc: 3 documentos visibles cotización, nota de venta y pedidos - Con ruc: Todos los documentos visibles | E31: FALSE | G31: FALSE
B32: Plantillas de impresion | C32: - Configuración simple - Configuración avanzada | E32: FALSE | G32: FALSE
B33: Configuración cuenta
B34: Crear empresa | C34: - Inicialmente se visualiza el modal de 5 pasos - Verificar que en series electronicas se visualice Nota de venta - Verificar que en series electronicas se visualice Pedido - Con ruc: todas las series hablitadas - Sin ruc: solo cotizacion, nota de venta y pedidos habilitadas | E34: FALSE | G34: FALSE
B35: Login
B36: Registrar cuenta | C36: - Muestra modal exitoso y redirige al home | E36: FALSE | G36: FALSE
B37: Continuar con Gmail y Facebook | C37: - Al finalizar redirige al home | E37: FALSE | G37: FALSE
B38: Cajas de ventas
B39: Abrir o reanudar caja | C39: - Ver total de comprobantes emitidos - Ver total de monto ingresado a caja - Ver ítems más vendidos | E39: FALSE | G39: FALSE
B40: Ventas
...

Sheet Reporte 
C1: Informe 01: Estados de Revisión vs Criticidad
C5: INICIO ITERACIÓN 07/07/2021 | D5: CRITICIDAD | F5: TOTAL
C6: Estado Revisión | D6: =Configuraciones!B4 -> No crítico | E6: =Configuraciones!B3 -> Crítico
C7: Observado | D7: =COUNTIFS('Test Run'!$F:$F,D$6,'Test Run'!$H:$H,$C7) -> 0 | E7: =COUNTIFS('Test Run'!$F:$F,E$6,'Test Run'!$H:$H,$C7) -> 0 | F7: =SUM(D7:E7) -> 0
C8: Falló | D8: =COUNTIFS('Test Run'!$F:$F,D$6,'Test Run'!$H:$H,$C8) -> 0 | E8: =COUNTIFS('Test Run'!$F:$F,E$6,'Test Run'!$H:$H,$C8) -> 0 | F8: =SUM(D8:E8) -> 0
C9: Incompleto | D9: =COUNTIFS('Test Run'!$F:$F,D$6,'Test Run'!$H:$H,$C9) -> 0 | E9: =COUNTIFS('Test Run'!$F:$F,E$6,'Test Run'!$H:$H,$C9) -> 0 | F9: =SUM(D9:E9) -> 0
C10: Corregido | D10: =COUNTIFS('Test Run'!$F:$F,D$6,'Test Run'!$H:$H,$C10) -> 0 | E10: =COUNTIFS('Test Run'!$F:$F,E$6,'Test Run'!$H:$H,$C10) -> 0 | F10: =SUM(D10:E10) -> 0
C11: Postergado | D11: =COUNTIFS('Test Run'!$F:$F,D$6,'Test Run'!$H:$H,$C11) -> 0 | E11: =COUNTIFS('Test Run'!$F:$F,E$6,'Test Run'!$H:$H,$C11) -> 0 | F11: =SUM(D11:E11) -> 0
C12: No procede | D12: =COUNTIFS('Test Run'!$F:$F,D$6,'Test Run'!$H:$H,$C12) -> 0 | E12: =COUNTIFS('Test Run'!$F:$F,E$6,'Test Run'!$H:$H,$C12) -> 0 | F12: =SUM(D12:E12) -> 0
C13: TOTAL | D13: =SUM(D7:D11) -> 0 | E13: =SUM(E7:E11) -> 0 | F13: =SUM(F7:F12) -> 0
C14: =Configuraciones!E17
C26: Informe 02: Estado de desarrollo
C28: ESTADO DESARROLLO | D28: Sin Responsable | E28: Roy Ibañez | F28: Moises | P28: OBS. TOTAL
C29: =Configuraciones!F7 -> No procede | D29: =COUNTIFS('Test Run'!$M:$M,$C29,'Test Run'!$O:$O,D$28) -> 0 | E29: =COUNTIFS('Test Run'!$M:$M,$C29,'Test Run'!$O:$O,E$28) -> 0 | F29: =COUNTIFS('Test Run'!$M:$M,$C29,'Test Run'!$O:$O,F$28) -> 0 | P29: =COUNTIFS('Test Run'!$M:$M,C29) -> 0
C30: =Configuraciones!F8 -> Postergado | D30: =COUNTIFS('Test Run'!$M:$M,$C30,'Test Run'!$O:$O,D$28) -> 0 | E30: =COUNTIFS('Test Run'!$M:$M,$C30,'Test Run'!$O:$O,E$28) -> 0 | F30: =COUNTIFS('Test Run'!$M:$M,$C30,'Test Run'!$O:$O,F$28) -> 0 | P30: =COUNTIFS('Test Run'!$M:$M,C30) -> 0
C31: =Configuraciones!F6 -> Corregido | D31: =COUNTIFS('Test Run'!$M:$M,$C31,'Test Run'!$O:$O,D$28) -> 0 | E31: =COUNTIFS('Test Run'!$M:$M,$C31,'Test Run'!$O:$O,E$28) -> 0 | F31: =COUNTIFS('Test Run'!$M:$M,$C31,'Test Run'!$O:$O,F$28) -> 0 | P31: =COUNTIFS('Test Run'!$M:$M,C31) -> 0
C32: =Configuraciones!F5 -> Corregido sin Subir | D32: =COUNTIFS('Test Run'!$M:$M,$C32,'Test Run'!$O:$O,D$28) -> 0 | E32: =COUNTIFS('Test Run'!$M:$M,$C32,'Test Run'!$O:$O,E$28) -> 0 | F32: =COUNTIFS('Test Run'!$M:$M,$C32,'Test Run'!$O:$O,F$28) -> 0 | P32: =COUNTIFS('Test Run'!$M:$M,C32) -> 0
C33: =Configuraciones!F9 -> Rechazado por QA | D33: =COUNTIFS('Test Run'!$M:$M,$C33,'Test Run'!$O:$O,D$28) -> 0 | E33: =COUNTIFS('Test Run'!$M:$M,$C33,'Test Run'!$O:$O,E$28) -> 0 | F33: =COUNTIFS('Test Run'!$M:$M,$C33,'Test Run'!$O:$O,F$28) -> 0 | P33: =COUNTIFS('Test Run'!$M:$M,C33) -> 0
C34: =Configuraciones!F4 -> En Curso | D34: =COUNTIFS('Test Run'!$M:$M,$C34,'Test Run'!$O:$O,D$28) -> 0 | E34: =COUNTIFS('Test Run'!$M:$M,$C34,'Test Run'!$O:$O,E$28) -> 0 | F34: =COUNTIFS('Test Run'!$M:$M,$C34,'Test Run'!$O:$O,F$28) -> 0 | P34: =COUNTIFS('Test Run'!$M:$M,C34) -> 0
C35: =Configuraciones!F3 -> Pendiente | D35: =COUNTIFS('Test Run'!$M:$M,$C35,'Test Run'!$O:$O,D$28) -> 0 | E35: =COUNTIFS('Test Run'!$M:$M,$C35,'Test Run'!$O:$O,E$28) -> 0 | F35: =COUNTIFS('Test Run'!$M:$M,$C35,'Test Run'!$O:$O,F$28) -> 0 | P35: =COUNTIFS('Test Run'!$M:$M,C35) -> 0
C36: TOTAL DE OBSERVACIONES | D36: =SUM(D31:D35) -> 0 | E36: =SUM(E31:E35) -> 0 | F36: =SUM(F31:F35) -> 0 | P36: =SUM(P31:P35) -> 0
K38: Roy Ibañez
K39: Alexis
K40: Jorge Suanha
K41: Kevin
K42: Luis Yanque
K43: Bryan
D44: =IF(COUNTIFS('Test Run'!$M:$M,$C31,'Test Run'!$O:$O,D$28)=0," ",COUNTIFS('Test Run'!$M:$M,$C31,'Test Run'!$O:$O,D$28)) | K44: Marielena
D45: =SUM(F7:F9) -> 0 | K45: Melany
C46: FALTAN | D46: =SUM(P32:P35) -> 0 | E46: POR VALIDAR POR QA | K46: EquipoBack

Sheet Regresión ERP1
B1: FACTURACIÓN | D1: Responsable | E1: Ok crt | F1: Responsable | G1: Ok Prd | H1: Obervaciones
B2: Boleta de adelanto 18% | C2: - Estado aceptado en SUNAT - Estado pendiente de pago en Búsqueda de comprobantes - Usar ese adelanto - Ver bitácora - Ver comprobante ( Descargar PDF, Descargar XML, Descargar CDR, Imprimir A4, Imprimir Ticket, Vista impresión, enviar por correo, mensaje WhatsApp) - Ver fecha y hora de emisión | E2: FALSE | G2: FALSE
B3: Factura al contado con 4 dias atras item gravado, exonerado e inafecto 10% | C3: - Estado aceptado en SUNAT - Estado pendiente de pago en Búsqueda de comprobantes - Ver movimiento de stock de inventario y kardex - Ver comprobantes ( Descargar PDF, Descargar XML, Descargar CDR, Imprimir A4, Imprimir Ticket, Vista impresión, enviar por correo, mensaje WhatsApp) | E3: FALSE | G3: FALSE
B4: Factura al crédito 5 cuotas items combos, equivalencias 18 % | C4: - Descarga de PDF, XML, CDR - Listado en Búsqueda de comprobantes. - Ver descargo de stock | E4: FALSE | G4: FALSE
B5: Boleta contado guardar descuento ítem y global 18% | C5: - Ver comprobante desde el ojito de búsqueda (datos correctos) - Listado en Búsqueda de comprobantes. | E5: FALSE | G5: FALSE
B6: Cotización con RUC | C6: - Enviar por whatsApp (verificar que descargue el pdf) - Listado de la cotización en búsqueda - Realizar copia - Ver comprobante ( Descargar PDF, Vista impresión, enviar por correo, mensaje WhatsApp) | E6: FALSE | G6: FALSE
B7: Boleta a partir de cotización con 5 dias atras | C7: - Listado en búsqueda de comprobantes - Ver movimiento de stock de inventario y kardex | E7: FALSE | G7: FALSE
B8: Factura a partir de cotización con retención editado | C8: - Ver pdf con datos correctos de la retención - Envío por correo | E8: FALSE | G8: FALSE
B9: Factura con detracción 10% | C9: - Ver pdf con datos correctos de la detraccción - Estado SUNAT aceptado en búsqueda de comprobantes | E9: FALSE | G9: FALSE
B10: Boleta con detracción en dólares | C10: - Ver pdf con datos correctos de la detraccción - Estado SUNAT aceptado en búsqueda de comprobantes | E10: FALSE | G10: FALSE
B11: Ticket a partir de cotización | C11: - Opciones de Imprimir Ticket e Imprimir PDF | E11: FALSE | G11: FALSE
B12: Guía de remisión remitente ventas privada | C12: - Listado en búsqueda de comprobantes - Descarga de PDF, XML post emisión - Ver comprobante ( Descargar PDF, Descargar XML, Descargar CDR, Imprimir A4, Imprimir Ticket, Vista impresión, enviar por correo, mensaje WhatsApp) - Ver hora y fecha de emisión | E12: FALSE | G12: FALSE
B13: Guía de remisión remitente exportación publica | C13: - Listado en búsqueda de comprobantes - Imprimir Ticket, Imprimir A4 | E13: FALSE | G13: FALSE
... B18: Regenerar PDF | C18: -Cambiar plantilla de Boleta, Factura, Guia -Ver PDF regenerado | E18: FALSE | G18: FALSE
B19: Clonación de documento | E19: FALSE | G19: FALSE
B20: Transformación de documento | E20: FALSE | G20: FALSE
B21: Nota de crédito motivo anulación de la operación fecha actual desde nuevo comprobante | C21: - Listado en búsqueda de comprobantes - Imprimir Ticket, Imprimir A4 - Descarga de PDF, XML, CDR - Estado de pago en búsqueda de comprobantes - Ver comprobante ( Descargar PDF, Descargar XML, Descargar CDR, Imprimir A4, Imprimir Ticket, Vista impresión, enviar por correo, mensaje WhatsApp) | E21: FALSE | G21: FALSE
B22: Nota de crédito motivo: error en la descripción desde búsqueda de comprobantes | C22: - Listado en búsqueda de comprobantes - Imprimir Ticket, Imprimir A4 | E22: FALSE | G22: FALSE
B23: Nota de crédito afectado a boleta devolución por ítem fecha actual desde nuevo comprobante | C23: - Listado en búsqueda de comprobantes - Imprimir Ticket, Imprimir A4 - Ver movimiento de stock de inventario y kardex - Ver comprobante ( Descargar PDF, Descargar XML, Descargar CDR, Imprimir A4, Imprimir Ticket, Vista impresión, enviar por correo, mensaje WhatsApp) | E23: FALSE | G23: FALSE
B24: Nota de débito fecha actual desde buscador | C24: - Descarga de PDF, XML, CDR - Estado de pago en búsqueda de comprobantes | E24: FALSE | G24: FALSE
B25: Nota de crédito motivo: Corrección en monto de pago para factural | C25: - Listado en búsqueda de comprobantes | E25: FALSE | G25: FALSE
B26: Descarga masiva de archivos desde búsqueda de comprobantes | C26: - Descarga correcta de los archivos de los comprobantes seleccionados | E26: FALSE | G26: FALSE
B27: Comunicación de baja | C27: - Ver movimiento de dinero sí el comprobante dado de baja está como pagado - Ver retorno de stock en inventario | E27: FALSE | G27: FALSE
B28: Factura - emisión masiva csv | C28: - Ver estado Generado en búsqueda de comprobantes - Ver estado Aceptado y estado de pago al emitir manualmente | E28: FALSE | G28: FALSE
B29: Nota de credito - emisión masiva csv | C29: - Ver estado Generado en búsqueda de comprobantes - Ver estado Aceptado y estado de pago al emitir manualmente | E29: FALSE | G29: FALSE
B30: Comunicacion de baja - emisión masiva csv | E30: FALSE | G30: FALSE
B31: Emitir comprobantes desde boton EMITIR SUNAT MASIVO | C31: -Verificar la emision de boleta, factura | E31: FALSE | G31: FALSE
B32: Reporte General Contable | C32: - Verificar que genere el reporte - Verificar los filtros - Verificar que los ultimos documentos emitidos esten - Verificar la descarga del excel - Ver que el excel tenga contenido | E32: FALSE | G32: FALSE
B33: Reporte de Cierre de Día | C33: - Verificar que genere el reporte - Verificar los filtros - Verificar que los ultimos documentos emitidos esten - Verificar los sub reportes - Verificar la descarga del excel - Ver que el excel tenga contenido | E33: FALSE | G33: FALSE
B34: Reporte de Ventas | C34: - Verificar que genere el reporte - Verificar los filtros - Verificar que los ultimos documentos emitidos esten - Verificar la descarga del excel y PDFs - Ver que el excel tenga contenido y PDFs | E34: FALSE | G34: FALSE
B35: Reporte de Ventas Detallado | C35: - Verificar que genere el reporte - Verificar los filtros - Verificar que los ultimos documentos emitidos esten - Verificar la descarga del excel - Ver que el excel tenga contenido | E35: FALSE | G35: FALSE
B36: Reporte de Utilidad por Producto | C36: - Verificar que genere el reporte - Verificar los filtros - Verificar que los ultimos documentos emitidos esten - Verificar la descarga del excel - Ver que el excel tenga contenido | E36: FALSE | G36: FALSE
B37: Reporte Estados SUNAT | C37: - Verificar que genere el reporte - Verificar los filtros - Verificar que los ultimos documentos emitidos esten | E37: FALSE | G37: FALSE
B38: Reporte Dinámico ítem | C38: - Verificar que genere el reporte - Verificar los filtros - Verificar que los ultimos documentos emitidos esten - Verificar la descarga del excel - Ver que el excel tenga contenido | E38: FALSE | G38: FALSE
B39: Emisión de boleta por integración | E39: FALSE | G39: FALSE
B40: Emisión de factura por integración | E40: FALSE | G40: FALSE
B41: Emisión de guías de remisión por integración | E41: FALSE | G41: FALSE
B42: Punto de Venta | D42: Responsable | E42: Ok crt | F42: Responsable | G42: Ok Prd
B43: Ticket de venta pago yape con DNI válido | C43: - Ver movimiento de dinero en cierre de caja con medio de pago yape - Ver descarga de inventario - Imprimir Ticket, Imprimir A4 - Descarga de PDF | E43: FALSE | G43: FALSE
B44: Boleta crédito clientes varios | C44: - Ver descarga de inventario - Imprimir Ticket, Imprimir A4 - Descarga de PDF, XML, CDR - Enviar correo - Ver cuotas desde búsqueda de comprobantes | E44: FALSE | G44: FALSE
...

Sheet Regresión Tienda Link
B1: BACK | D1: Responsable | E1: Ok crt | F1: Responsable | G1: Ok Prd | H1: Obervaciones
B2: Crear tienda | C2: - Crear una tienda y verificar la visibilidad de la misma | E2: FALSE | G2: FALSE
B3: Agregar/ modificar ítems de tu tienda | C3: - Verificar que en modal de "Habilitar ítems" sigan apareciendo los ítems * Producto - Normales - Equivalencia (deben aparecer todos) - Variantes (Solo los hijos) - Selectores (aparece como un ítem normal) * Servicio * Combo * Receta | E3: FALSE | G3: FALSE
B4: Reporte de pedidos | E4: FALSE | G4: FALSE
B5: Reporte de pedidos por producto | E5: FALSE | G5: FALSE
B6: Ver pedido | C6: - Visualizar pedido desde Punto de venta - Verificar los datos del cliente (sin documento) - Ver detalles del pedidos en observaciones | E6: FALSE | G6: FALSE
B7: Facturar pedido | C7: - Convertir pedido a Boleta/Factura/Nota de venta | E7: FALSE | G7: FALSE
B8: FRONT | D8: Responsable | E8: Ok crt | F8: Responsable | G8: Ok Prd
B9: Ver productos de distintos tipos | C9: - Ver ítem habilitados en tienda - Ver solo categorias de los ítems activados | E9: FALSE | G9: FALSE
B10: Ver Equivalencias y variantes | C10: - En variantes solo se muestran los hijos - En equivalencia se muestran todos - La informacion adicional de tienda se comparte entre todos lo mismo | E10: FALSE | G10: FALSE
B11: Ver combos y recetas | C11: - Tienen un detallado de los items que contienen - Si es con stock automatico, se debe regir según el stock de los ítems que componen el combo/receta | E11: FALSE | G11: FALSE
B12: Realizar pedidos | C12: - Permitir crear pedidos | E12: FALSE | G12: FALSE

Sheet Resumen
B2: ='Test Case'!B2 | H2: =TODAY() -> 46109 | L2: Fecha | M2: Descripción
L3: 45658 | M3: Año Nuevo
L4: 45764 | M4: Jueves Santo
B5: Estado | C5: Cantidad | L5: 45765 | M5: Viernes Santo
B6: Corregido | C6: =COUNTIFS('Test Run'!M1:M999, B6) -> 0 | L6: 45778 | M6: Día del Trabajo
B7: Corregido sin Subir | C7: =COUNTIFS('Test Run'!M1:M999, B7) -> 0 | L7: 45837 | M7: San Pedro y San Pablo
B8: En Curso | C8: =COUNTIFS('Test Run'!M1:M999, B8) -> 0 | L8: 45866 | M8: Fiestas Patrias (Primer día)
B9: No procede | C9: =COUNTIFS('Test Run'!M1:M999, B9) -> 0 | L9: 45867 | M9: Fiestas Patrias (Segundo día)
B10: Postergado | C10: =COUNTIFS('Test Run'!M1:M999, B10) -> 0 | L10: 45899 | M10: Santa Rosa de Lima
B11: Pendiente | C11: =COUNTIFS('Test Run'!M1:M999, B11) -> 0 | L11: 45938 | M11: Combate de Angamos
B12: Rechazado por QA | C12: =COUNTIFS('Test Run'!M1:M999, B12) -> 0 | L12: 45962 | M12: Día de Todos los Santos
L13: 45999 | M13: Inmaculada Concepción
L14: 46000 | M14: Batalla de Ayacucho
L15: 46016 | M15: Navidad
B19: Total de observaciones | C19: =SUM(C2:C16) -> 0
B20: Pendientes con más de 3 días | C20: {=SUMPRODUCT(('Test Run'!M2:M1000="Pendiente") * (NETWORKDAYS('Test Run'!K2:K1000, TODAY()-1, L3:L999) > 3))} -> 0

Sheet Reporte
A1: REPORTE QA - SUBIDA
A3: Información General
A4: MVP
A5: Fecha/hora inicio
A6: Fecha/hora fin
A7: Responsable QA
A8: Apoyo QA
A9: Responsable Agile
A11: Alcance del Release
A12: Módulos afectados Ejm: Facturación, PuntoVenta, Configuraciones
A14: Pruebas realizadas
A16: Tipo | B16: Ejecutado | C16: Evidencias (screenshots, logs)
A17: Regresión Manual (checklist) | B17: FALSE
A18: Regresión Automatizada | B18: FALSE
A19: Integración API | B19: FALSE
A20: Estrés | B20: FALSE
A22: Observaciones
A23: * Comportamientos raros * UX/usabilidad * Validaciones iincompletas * Performance leve * Dependencias externas, cuando no se puede probar los servicios externos en producción * Datos inconsistentes * Funcionalidad parcial o incompleta * Casos no cubiertos * Observaciones del agile
A26: Validaciones en producción Post Deploy
A27: Tipo | B27: Ejecutado | C27: Evidencias (screenshots, logs)
A28: BD actualizada | B28: FALSE
A29: Kafka estable | B29: FALSE
A30: Redis correcto | B30: FALSE

Sheet Configuraciones
B2: Criticidad | C2: Nivel Detección | D2: Tipo Incidencia | E2: Estado Revisión | F2: Estado Desarrollo | G2: Responsables de revision | H2: Responsable de Correcciones
B3: Crítico | C3: Alta | D3: FUNCIONAL | E3: Corregido | F3: Pendiente | G3: Flor | H3: Sin Responsable
B4: No crítico | C4: Intermedia | D4: DISEÑO | E4: Observado | F4: En Curso | G4: Vicky | H4: Kevin
C5: Baja | D5: OTROS | E5: Falló | F5: Corregido sin Subir | G5: Marielena | H5: Gean
C6: Mejora | E6: Incompleto | F6: Corregido | G6: Emily | H6: Diego
E7: No procede | F7: No procede | G7: Kevin | H7: Romel
E8: Postergado | F8: Postergado | G8: Jhunior | H8: Luiggi
F9: Rechazado por QA | G9: Equipo
G10: Maria
G11: Italo(Comercial)

Sheet Validacione Front y Back
A1: FRONT
A2: PASOS | B2: FUNCIONALIDAD | C2: VALIDACIONES
A3: PASO 1 | B3: ELEGIR TIPO ITEM | C3: ELEGIR TIPO ITEM | D3: TRUE
A5: PASO 2 | B5: PERSONALIZAR PLANTILLA | C5: PARA PRODUCTOS Y SERVICIOS -> CAMPOS OBLIGATORIOS SON DESCRIPCION, PRECIO SOLES Y TIPO AFECTACION. PARA INSUMOS -> CAMPOS OBLIGATORIOS SON DESCRIPCION Y TIPO AFECTACION. | D5: TRUE
C6: SI FAMILIA O CATEGORIA SE MARCAN TIENEN QUE MARCARSE LOS DOS, SI SUBCATEGORIA SE MARCA TAMBIEN FAMILIA Y CATEGORIA Y SI TIPO SE MARCA TAMBIEN LOS 3 ANTERIORES. DEBEN SEGUIR LAS MISMAS REGLAS AL DESMARCARSE. | D6: TRUE
C7: LOS CAMPOS LOTE, FECHA VENCIMIENTO Y STOCK TIENEN RELACION, SI SE MARCA FECHA O STOCK TIENE QUE MARCARSE STOCK Y CONTROL DE LOTES, SI SOLO SE MARCA STOCK NO SE MARCA FECHA , LOTE Y CONTROL DE LOTES. | D7: TRUE
C8: PARA SERVICIOS -> NO SE DEBEN MOSTRAR LOS CAMPOS LOTE, STOCK, FECHA DE VENCIMIENTO, CONTROL DE LOTES, CONTROL DE STOCK ESTRICTO Y FLEXIBLE. PARA INSUMOS -> NO SE DEBEN MOSTRAR LOS CAMPOS DE PRECIOS SOLES, DOLARES Y EUROS. | D8: TRUE
C9: PARA EL CAMPO UNIDAD DEBE SELECCIONARSE TAMBIEN EL CAMPO EQUIVALENTE SUNAT, A SU VEZ SI SE DESMARCA UNIDAD DEBE DESMARCARSE EQUIVALENTE SUNAT PERO SI SE DESMARCA EQUIVALENTE SUNAT NO SE DESMARCA UNIDAD
B11: CARGAR PLANTILLA | C11: VERIFICAR ARCHIVO EN BLANCO | D11: TRUE
C12: VERIFICAR ARCHIVO TENGA CABECERA | D12: TRUE
C13: VERFIFICAR NUMERO DE ITEMS NO SUPERE LOS 1000 | D13: TRUE
C14: VERIFICAR EXTENSION DE ARCHIVO EXCEL | D14: TRUE
C15: VERIFICAR QUE SE CARGUE UN ARCHIVO | D15: TRUE
A17: PASO 3 | B17: AGIGNAR COLUMNAS | C17: CAMPOS OBLIGATORIOS SE MANTIENE MISMA REGLA QUE PERSONALIZAR PLANTILLA | D17: TRUE
C18: SE MANTIENE MISMA RELACION QUE PERSONALIZAR PLANTILLA, OSEA FAMILIA, CATEGORIA, SUBCATEGORIA Y TIPO | D18: TRUE
C19: SE MANTIENE MISMA RELACION QUE PERSONALIZAR PLANTILLA, OSEA FECHA VENCIMIENTO, LOTE Y STOCK | D19: TRUE
C20: VERIFICAR SELECCIÓN DE CABECERAS REPETIDAS | D20: TRUE
C21: PUEDEN SER SELECCIONES REPETIDAS LA OPCION IGNORAR COLUMNA | D21: TRUE
C22: UNIDAD Y EQUIVALENTE SUNAT MANTIENE MISMA RELACION QUE PERSONALIZAR
A24: PASO 4 | B24: ASIGNAR ALMACENES | C24: SOLO SE MOSTRARAN ALMACENES EN TIPO DE ÍTEM PRODUCTOS E INSUMOS, PARA SERVICIOS, COMBOS Y RECETAS SE MOSTRARAN SUCURSALES | D24: TRUE
C25: ELEGIR AL MENOS UN ALMACEN O SUCURSAL DEPENDIENDO DEL TIPO DE ÍTEM
A30: BACK
A31: EN GENERAL SI UN CAMPO SE SELECCIONA PARA IMPORTAR ESTE DEBE TENER UN VALOR NO PUEDE SER VACIO
A32: CAMPOS | B32: VALIDACION | D32: FALSE
A33: TIPO CODIGO BARRAS | B33: SOLO ACEPTA VALORES GTIN-8 Y PROPIO | D33: FALSE
A34: CODIGO DE BARRAS | B34: NO DEBE ESTAR REPETIDO EN EL EXCEL | D34: FALSE
A35: CODIGO SUNAT | B35: DEBE ESTAR REGISTRADO EN EL SISTEMA | C35: SI TIPO CODIGO BARRAS ES PROPIO: SE VALIDARA SI EL CODIGO SUNAT EXISTE EN EL CATALOGO SUNAT, NO PUEDE CREARSE. SI TIPO CODIGO BARRAS ES GTIN8: EL CODIGO SUNAT TOMARA EL VALOR DEL CODIGO DE BARRAS ASI SE HAYA COLOCADO UN VALOR EN EL CAMPO | D35: FALSE
A36: CODIGO ITEM | B36: >NO SOBREPASAR 50 CARACTERES >NO CONTENER CARACTERES NO VALIDOS >NO SER RESERVADO PARA EL SISTEMA >NO DEBE EXISTIR EN EL SISTEMA >NO DEBE ESTAR REPETIDO EN EL EXCEL | D36: FALSE
A37: UNIDAD | B37: DEBE ESTAR REGISTRADO EN EL SISTEMA | D37: FALSE
A38: MARCA | B38: DEBE ESTAR REGISTRADO EN EL SISTEMA | D38: FALSE
A39: PRECIO VENTA SOLES | B39: >NO PUEDE SER UN VALOR NEGATIVO >NO PUEDE SER UN TEXTO O STRING | D39: FALSE
A40: PRECIO VENTA DOLARES | B40: >NO PUEDE SER UN VALOR NEGATIVO >NO PUEDE SER UN TEXTO O STRING | D40: FALSE
A41: PRECIO VENTA EUROS | B41: >NO PUEDE SER UN VALOR NEGATIVO >NO PUEDE SER UN TEXTO O STRING | D41: FALSE
A42: COSTO INICIAL SOLES | B42: >NO PUEDE SER UN VALOR NEGATIVO >NO PUEDE SER UN TEXTO O STRING | D42: FALSE
A43: COSTO INICIAL DOLARES | B43: >NO PUEDE SER UN VALOR NEGATIVO >NO PUEDE SER UN TEXTO O STRING | D43: FALSE
A44: COSTO INICIAL EUROS | B44: >NO PUEDE SER UN VALOR NEGATIVO >NO PUEDE SER UN TEXTO O STRING | D44: FALSE
A45: STOCK MINIMO | B45: >NO PUEDE SER UN VALOR NEGATIVO >NO PUEDE SER UN TEXTO O STRING | D45: FALSE
A46: TIPO PRECIO UNITARIO | B46: SOLO ACEPTA "PRECIO UNITARIO (VENTAS)" Y "PRODUCTO PARA REGALO O BONIFICACION" | D46: FALSE
A47: TIPO AFECTACION IGV | B47: >SI PRECIO UNITARIO ES PRECIO VENTAS SOLO ACEPTA: {"GRAVADO - PAGA IGV"}, {"EXONERADO - NO PAGA IGV"}, {"INAFECTO - NO PAGA IGV"} >SI PRECIO UNITARIO ES REGALO O BONIFICACION SOLO ACEPTA: {"GRAVADO - RETIRO POR PREMIO"}, {"GRAVADO - RETIRO POR DONACION"}, {"GRAVADO - RETIRO"}, {"GRAVADO - RETIRO POR PUBLICIDAD"}, {"GRAVADO - BONIFICACIONES"}, {"GRAVADO - RETIRO POR ENTREGA A TRABAJADORES"}, {"EXONERADO - TRANSFERENCIA GRATUITA"}, {"INAFECTO - RETIRO POR BONIFICACION"}, {"INAFECTO - RETIRO"}, {"INAFECTO - RETIRO POR MUESTRAS MEDICAS"}, {"INAFECTO - RETIRO POR CONVENIO COLECTIVO"}, {"INAFECTO - RETIRO POR PREMIO"}, {"INAFECTO - RETIRO POR PUBLICIDAD"}, {"EXPORTACION"} | D47: FALSE
... A54: TIPO | B54: DEBE ESTAR REGISTRADO EN EL SISTEMA PARA LA SUBCATEGORIA DESIGNADA | D54: FALSE
...

Sheet Hoja 14
A2: precio unitario | B2: 118 | C2: gravadas | D2: 0.8
A3: Precio con igv | B3: =B2/1.18 -> 100 | C3: isc | D3: =D2*0.1 -> 0.08
A4: isc | B4: =(B3*0.1) -> 10 | C4: suma | D4: =D2+D3 -> 0.88
A5: valor unitario | B5: =B3-B4 -> 90 | C5: igv | D5: =D4*0.18 -> 0.1584
C7: total | D7: =D4+D5 -> 1.0384
A13: BIEN 130423 PUG CF - A
A14: INSUMO 130423 PUG CF - B
A15: SERVICIO 130423 PUG CF - C
A16: BIEN 130423 ISC(SISTEMA AL VALOR) PUG CF - D
A17: BIEN 130423 ISC(APLICACION AL MONTO FIJO 10) PUG CF - E
A18: BIEN 130423 ISC(SISTEMA DE PRECIOS DE VENTA AL PUBLICO 3.5) PUG CF - F
A19: BIEN 130423 ISC(SISTEMA AL VALOR 7.5) PUG CE - G
A20: BIEN 130423 ISC(APLICACION AL MONTO FIJO 10) PUG CE - H
A21: BIEN 130423 ISC(SISTEMA DE PRECIOS DE VENTA AL PUBLICO 3.5) PUG CE - I

Sheet Criterios de Aceptacion
B1: MODULO(US) | C1: INTERFAZ | D1: SUBMÓDULO | E1: COMPONENTE | F1: TestCase | G1: Detalle | H1: REFERENCIAS | I1: REVISION
A2: Carlos | B2: Configuracion empresa 1 | C2: xxxxx | D2: DATOS DEL EMPRESA | E2: RUC | F2: Validar RUC | G2: Validar no este registrado (DUPLICADO) | H2: https://www.figma.com/file/IDOnz1HeOrs7C2tnulr16q/Temas-TiendaLink?node-id=361%3A11901 | I2: FALSE
G3: Validar si esta registrado en SMART.CLIC | I3: FALSE
F4: Validar Tamaño del campo | G4: Validar minimo de caracteres permitidos | I4: FALSE
G5: Validar maximo de caracteres permitidos | I5: FALSE
G6: Validar campo nulo | I6: FALSE
E7: Razon Social | F7: - | G7: - | I7: FALSE
E8: DIRECCION | F8: Validar Tamaño del campo | G8: Validar minimo de caracteres permitidos | I8: FALSE
G9: Validar maximo de caracteres permitidos | I9: FALSE
G10: Validar campo nulo | I10: FALSE
E11: Diseño | F11: Validar diseño | G11: Validar diseño segun figma | I11: FALSE
D12: PERSONA DE CONTACTO | E12: Nombre | F12: Validar nombre de la tarjeta | I12: FALSE
F13: Validar longitud min /max | I13: FALSE
F14: Validar vacio/nulo | I14: FALSE
F15: Validar espacios | I15: FALSE
I16: FALSE
F17: Revisar diseño del figma | I17: FALSE
E18: Correo | F18: Validar vacio | I18: FALSE
F19: Validar correo vacio | I19: FALSE
F20: Validar solo espacios | I20: FALSE
I21: FALSE
F22: Revisar diseño del figma | I22: FALSE
E23: Telefono | F23: Validar longitud | I23: FALSE
F24: Solo numeros | I24: FALSE
F25: Validar Vacio | I25: FALSE
I26: FALSE
F27: Revisar diseño del figma | I27: FALSE
A28: Carlos | D28: VINCULACIÓN SUNAT | E28: Usuario SOL | F28: Validar Tamaño del campo | G28: Validar minimo de caracteres permitidos | I28: FALSE
G29: Validar maximo de caracteres permitidos | I29: FALSE
G30: Validar campo nulo | I30: FALSE
F31: Usuario Valido | G31: Valdar que el usuario ingresado sea valido | I31: FALSE
E32: Clave Sol | F32: Validar Tamaño del campo | G32: Validar minimo de caracteres permitidos | I32: FALSE
G33: Validar maximo de caracteres permitidos | I33: FALSE
G34: Validar campo nulo | I34: FALSE
E35: Diseño | F35: Validar diseño | G35: Validar diseño segun figma | I35: FALSE
C36: xxxx | D36: SERIES ELECTRONICAS | E36: Serie | H36: https://www.figma.com/file/IDOnz1HeOrs7C2tnulr16q/Temas-TiendaLink?node-id=361%3A10363 | I36: FALSE
I37: FALSE
I38: FALSE
E39: Correlativo | I39: FALSE
I40: FALSE
...

Sheet PlanningVsPruebas
A3: Módulo | B3: Sub módulo (Test case) | C3: Tareas del Sprint | D3: Fibonacci | E3: Peso Front | F3: Peso Back | G3: Peso DevOps | H3: Incidencias | L3: S18 Back | M3: S18 Front | N3: S19 Back | O3: S19 Front
A4: Logística | B4: Productos y Servicios | C4: Aumentar moneda Peso Chileno - front | D4: 8 | E4: 8 | F4: 0 | G4: 0 | H4: 3 | K4: Logística
A5: Logística | B5: Productos y Servicios | C5: Aumentar moneda Peso Chileno - back | D5: 5 | E5: 0 | F5: 5 | G5: 0 | K5: Facturación
A6: Logística | B6: Movimientos | C6: Aumentar moneda Peso Chileno | D6: 13 | E6: 8 | F6: 5 | H6: 0 | K6: Punto de Venta
A7: Facturación | B7: Nuevos documentos | C7: tarea 4 | H7: 1
A8: Facturación | B8: Nuevos documentos | C8: tarea 5

Sheet Total Test 
A1: MÓDULO | B1: SUB MÓDULO | C1: SUB SUB MÓDULO | D1: COD INTERFAZ | E1: NOMBRE CAMPO | F1: TIPO CAMPO | G1: REGLAS DE NEGOCIO
A2: Facturación | B2: Nuevo comprobante | C2: Factura | E2: Número de documento | F2: Cuadro texto | G2: Si el documento no existe, muestra interfaz para registrar nuevo documento.
A3: Facturación | B3: Nuevo comprobante | C3: Factura | E3: Número de documento | F3: Cuadro texto | G3: Si existe documento, completa datos de otros campos.
A4: Productos y Stock | B4: Productos/Servicios | C4: Productos o Servicios | E4: Ingreso/Salida rápido/a | F4: Botón de acción | G4: Los ítems con lotes no tienen habilitado estos botones de acción, igual que equivalencias.
